<mujoco model="arx5_robosuite_tabletop">
  <compiler angle="radian" autolimits="true" meshdir="../../source/uwlab_assets/uwlab_assets/robots/arx5/assets"/>

  <option timestep="0.008333333333333333" gravity="0 0 0"/>

  <custom>
    <numeric name="arx5_base_pose_reference" data="-0.535 -0.21 0.8 1.0 0.0 0.0 0.0"/>
    <numeric name="table_pose_reference" data="0.0 0.0 0.799375 1.0 0.0 0.0 0.0"/>
    <numeric name="workspace_x_range" data="-0.4 -0.2"/>
    <numeric name="workspace_y_range" data="-0.3 -0.1"/>
    <numeric name="robot_xy_jitter_m" data="0.02"/>
    <numeric name="control_dt_reference" data="0.1"/>
  </custom>

  <asset>
    <texture name="floor_grid" type="2d" builtin="checker" width="512" height="512" rgb1="0.72 0.72 0.70" rgb2="0.62 0.62 0.60"/>
    <material name="floor_mat" texture="floor_grid" texrepeat="3 3" reflectance="0.05"/>
    <material name="table_silver" rgba="0.75 0.75 0.72 1" reflectance="0.15" shininess="0.35" specular="0.5"/>
    <material name="table_legs_metal" rgba="0.55 0.55 0.55 1" reflectance="0.3" shininess="0.6" specular="0.4"/>
    <material name="curtain_mat" rgba="0.72 0.72 0.70 1"/>
    <material name="receptive_cube_red" rgba="1.0 0.0 0.0 1.0"/>
    <material name="insertive_cube_green" rgba="0.0 1.0 0.0 1.0"/>
    <material name="workspace_marker_mat" rgba="0.0 0.2 1.0 0.65"/>

    <mesh name="base_link_mesh" file="meshes/base_link.obj"/>
    <mesh name="link1_mesh" file="meshes/link1.obj"/>
    <mesh name="link2_mesh" file="meshes/link2.obj"/>
    <mesh name="link3_mesh" file="meshes/link3.obj"/>
    <mesh name="link4_mesh" file="meshes/link4.obj"/>
    <mesh name="link5_mesh" file="meshes/link5.obj"/>
    <mesh name="link6_mesh" file="meshes/link6.obj"/>
    <mesh name="link7_mesh" file="meshes/link7.obj"/>
    <mesh name="link8_mesh" file="meshes/link8.obj"/>

    <material name="arx_black" rgba="0 0 0 1"/>
    <material name="arx_white" rgba="1 1 1 1"/>
    <material name="camera_mat" rgba="0.1 0.1 0.1 1"/>
    <material name="grasp_site_mat" rgba="0 0.8 1 0.7"/>
  </asset>

  <default>
    <joint damping="0.01" armature="0.01"/>
    <geom contype="1" conaffinity="1" friction="1 0.005 0.0001"/>
  </default>

  <worldbody>
    <light name="key_light" pos="-0.3 -0.4 3.0" dir="0.2 0.2 -1.0" directional="true" diffuse="0.8 0.8 0.8"/>
    <light name="fill_light" pos="0.5 0.6 2.0" diffuse="0.35 0.35 0.35"/>
    <geom name="floor" type="plane" size="2.0 2.0 0.01" material="floor_mat" pos="0 0 0"/>

    <!-- Robosuite table. Source MJCF body z=0.775 gives a tabletop at z=0.800, matching the current Isaac table root at z=0.799375. -->
    <body name="table" pos="0 0 0.775">
      <geom name="table_collision" pos="0 0 0" size="0.6 0.45 0.025" type="box" group="0" friction="1 0.005 0.0001"/>
      <geom name="table_visual" pos="0 0 0" size="0.6 0.45 0.025" type="box" conaffinity="0" contype="0" group="1" material="table_silver"/>
      <site name="table_top" pos="0 0 0.025" size="0.001 0.001 0.001" rgba="0 0 0 0"/>

      <geom name="table_leg1_visual" pos="0.5 0.35 -0.3875" size="0.025 0.3875" type="cylinder" conaffinity="0" contype="0" group="1" material="table_legs_metal"/>
      <geom name="table_leg2_visual" pos="-0.5 0.35 -0.3875" size="0.025 0.3875" type="cylinder" conaffinity="0" contype="0" group="1" material="table_legs_metal"/>
      <geom name="table_leg3_visual" pos="-0.5 -0.35 -0.3875" size="0.025 0.3875" type="cylinder" conaffinity="0" contype="0" group="1" material="table_legs_metal"/>
      <geom name="table_leg4_visual" pos="0.5 -0.35 -0.3875" size="0.025 0.3875" type="cylinder" conaffinity="0" contype="0" group="1" material="table_legs_metal"/>
    </body>

    <body name="external_cam" pos="0.5170 0.3270 1.3640" quat="0.3604 0.2030 0.5000 0.7609">
      <camera name="external_camera" mode="fixed" pos="0.0 0.0 0.0" quat="1.0 0.0 0.0 0.0" fovy="42.47"/>
    </body>

    <geom name="curtain_back" type="box" pos="-1.1 0.0 0.519" quat="1.0 0.0 0.0 0.0" size="0.005 0.8 1.0625" conaffinity="0" contype="0" group="1" material="curtain_mat"/>
    <geom name="curtain_left" type="box" pos="-0.05 0.8 0.519" quat="0.707 0.0 0.0 -0.707" size="0.005 1.05 1.0625" conaffinity="0" contype="0" group="1" material="curtain_mat"/>
    <geom name="curtain_right" type="box" pos="-0.05 -0.8 0.519" quat="0.707 0.0 0.0 -0.707" size="0.005 1.05 1.0625" conaffinity="0" contype="0" group="1" material="curtain_mat"/>

    <site name="workspace_xmin_ymin" pos="-0.4 -0.3 0.805" size="0.008" rgba="0.0 0.2 1.0 0.65"/>
    <site name="workspace_xmin_ymax" pos="-0.4 -0.1 0.805" size="0.008" rgba="0.0 0.2 1.0 0.65"/>
    <site name="workspace_xmax_ymin" pos="-0.2 -0.3 0.805" size="0.008" rgba="0.0 0.2 1.0 0.65"/>
    <site name="workspace_xmax_ymax" pos="-0.2 -0.1 0.805" size="0.008" rgba="0.0 0.2 1.0 0.65"/>

    <body name="receptive_cube" pos="-0.3 -0.2 0.84">
      <geom name="receptive_cube_collision" type="box" size="0.04 0.04 0.04" mass="0.05" friction="1 0.005 0.0001" material="receptive_cube_red" contype="0" conaffinity="0"/>
    </body>

    <body name="insertive_cube" pos="-0.3 -0.2 0.87">
      <geom name="insertive_cube_collision" type="box" size="0.04 0.04 0.04" mass="0.05" friction="1 0.005 0.0001" material="insertive_cube_green" contype="0" conaffinity="0"/>
    </body>

    <body name="arx5" pos="-0.535 -0.21 0.8" quat="1.0 0.0 0.0 0.0" gravcomp="1">
      <inertial pos="-3.0001e-05 3.0589e-05 0.027324" mass="0.43995" diaginertia="0.00017 0.00017 0.00016"/>
      <geom name="base_link_visual" type="mesh" mesh="base_link_mesh" material="arx_black" contype="0" conaffinity="0"/>
      <geom name="base_link_collision" type="box" pos="0.0 0.0 0.03" size="0.03 0.03 0.03" contype="0" conaffinity="0"/>

      <body name="link1" pos="0.0 0.0 0.0605" gravcomp="1">
        <joint name="joint1" type="hinge" axis="0.0 0.0 1.0" range="-10.0 10.0" ref="0.0"/>
        <inertial pos="0.0054231 -0.0080289 0.017086" mass="0.066982" diaginertia="0.00008 0.00003 0.00008"/>
        <geom name="link1_visual" type="mesh" mesh="link1_mesh" material="arx_black" contype="0" conaffinity="0"/>
        <geom name="link1_collision" type="box" pos="0.0 0.0 0.02" size="0.03 0.03 0.03" contype="0" conaffinity="0"/>

        <body name="link2" pos="0.02 0.0 0.04" gravcomp="1">
          <joint name="joint2" type="hinge" axis="0.0 1.0 0.0" range="-10.0 10.0" ref="1.0"/>
          <inertial pos="-0.13237 0.0020852 0.00010549" mass="1.0795" diaginertia="0.00051 0.01599 0.01605"/>
          <geom name="link2_visual" type="mesh" mesh="link2_mesh" material="arx_black" contype="0" conaffinity="0"/>
          <geom name="link2_collision" type="box" pos="-0.132 0.0 0.0" size="0.14 0.02 0.02" contype="0" conaffinity="0"/>

          <body name="link3" pos="-0.264 0.0 0.0" euler="3.1416 0 0" gravcomp="1">
            <joint name="joint3" type="hinge" axis="0.0 1.0 0.0" range="-10.0 10.0" ref="1.0"/>
            <inertial pos="0.18531 0.00068376 -0.051638" mass="0.54534" diaginertia="0.00036 0.00423 0.00420"/>
            <geom name="link3_visual" type="mesh" mesh="link3_mesh" material="arx_white" contype="0" conaffinity="0"/>
            <geom name="link3_collision" type="box" pos="0.15 0.0 -0.055" quat="0.7071068 0 0.7071068 0" size="0.02 0.02 0.09" contype="0" conaffinity="0"/>

            <body name="link4" pos="0.245 0.0 -0.056" gravcomp="1">
              <joint name="joint4" type="hinge" axis="0.0 1.0 0.0" range="-10.0 10.0" ref="0.0"/>
              <inertial pos="0.040231 0.0044807 -0.035335" mass="0.11714" diaginertia="0.00019 0.00023 0.00014"/>
              <geom name="link4_visual" type="mesh" mesh="link4_mesh" material="arx_black" contype="0" conaffinity="0"/>
              <geom name="link4_collision" type="box" pos="0.04 0.004 -0.03" size="0.03 0.03 0.03" contype="0" conaffinity="0"/>

              <body name="link5" pos="0.06775 0.0005 -0.0865" gravcomp="1">
                <joint name="joint5" type="hinge" axis="0.0 0.0 1.0" range="-10.0 10.0" ref="0.0"/>
                <inertial pos="0.003612 -1.5455e-05 0.055214" mass="0.63488" diaginertia="0.00083 0.00082 0.00026"/>
                <geom name="link5_visual" type="mesh" mesh="link5_mesh" material="arx_black" contype="0" conaffinity="0"/>
                <geom name="link5_collision" type="box" pos="0.004 0.0 0.055" size="0.025 0.025 0.03" contype="0" conaffinity="0"/>

                <body name="link6" pos="0.02895 0.0 0.0865" euler="-3.1416 0 0" gravcomp="1">
                  <joint name="joint6" type="hinge" axis="1.0 0.0 0.0" range="-1.5708 1.5708" ref="0.0"/>
                  <inertial pos="0.041697 2.4368e-05 0.00014464" mass="0.44089" diaginertia="0.00038 0.00028 0.00050"/>
                  <geom name="link6_visual" type="mesh" mesh="link6_mesh" material="arx_black" contype="0" conaffinity="0"/>
                  <geom name="link6_collision" type="box" pos="0.04 0.0 0.0" size="0.03 0.02 0.02" contype="0" conaffinity="0"/>
                  <site name="grasp_point" pos="0.145 0.0 0.0" size="0.006" material="grasp_site_mat"/>

                  <body name="camera_base" pos="0.057 0.0 0.0" euler="0 0 -3.1416" gravcomp="1">
                    <geom name="camera_base_visual" type="box" size="0.02 0.018 0.012" material="camera_mat" contype="0" conaffinity="0"/>
                    <body name="camera" pos="-0.0275 0.0 0.05" euler="0 0.3491 3.141592653589793" gravcomp="1">
                      <geom name="camera_visual" type="box" size="0.018 0.014 0.012" material="camera_mat" contype="0" conaffinity="0"/>
                      <camera name="wrist_camera" mode="fixed" pos="0.0 0.0 0.0" quat="1.0 0.0 0.0 0.0" fovy="42.47"/>
                    </body>
                  </body>

                  <body name="link7" pos="0.08657 0.024896 -0.0002436" gravcomp="1">
                    <joint name="joint7" type="slide" axis="0.0 1.0 0.0" range="0.0 0.044" ref="0.02"/>
                    <inertial pos="-0.00035522 -0.007827 -0.0029883" mass="0.064798" diaginertia="0.00002 0.00003 0.00003"/>
                    <geom name="link7_visual" type="mesh" mesh="link7_mesh" material="arx_black" contype="0" conaffinity="0"/>
                    <geom name="link7_collision" type="box" pos="0.035 -0.02 0.0" size="0.04 0.005 0.015" contype="1" conaffinity="2" friction="2.0 0.005 0.0001" solimp="0.95 0.99 0.001" solref="0.01 1"/>
                  </body>

                  <body name="link8" pos="0.08657 -0.0249 -0.00024366" gravcomp="1">
                    <joint name="joint8" type="slide" axis="0.0 -1.0 0.0" range="0.0 0.044" ref="0.02"/>
                    <inertial pos="-0.00035522 0.0078277 0.0024201" mass="0.064798" diaginertia="0.00002 0.00003 0.00003"/>
                    <geom name="link8_visual" type="mesh" mesh="link8_mesh" material="arx_black" contype="0" conaffinity="0"/>
                    <geom name="link8_collision" type="box" pos="0.035 0.02 0.0" size="0.04 0.005 0.015" contype="1" conaffinity="2" friction="2.0 0.005 0.0001" solimp="0.95 0.99 0.001" solref="0.01 1"/>
                  </body>
                </body>
              </body>
            </body>
          </body>
        </body>
      </body>
    </body>
  </worldbody>

  <keyframe>
    <key name="isaac_default" qpos="0.0 1.0 1.0 0.0 0.0 0.0 0.02 0.02"/>
  </keyframe>
</mujoco>
